<mujoco>
	<compiler inertiafromgeom="true" coordinate="local"/>

    <default>
        <joint limited='true' damping='1' armature='0'/>
        <geom contype='1' conaffinity='1' condim='1'
        	margin="0.001" solref=".02 1" solimp=".8 .8 .01" material="geom"/>
        <motor ctrlrange='-.4 .4' ctrllimited='true'/>
    </default>

	<size nconmax="500" njmax="5000"/>
	<option timestep="0.001"/>

    <statistic extent="5"/>

	<asset>
		<hfield name="fld" size="3 3 1.5 1"  file="../mesh/hfield.hf"/>

      	<texture name="texplane" type="2d" builtin="checker" rgb1=".8 .8 .8" rgb2=".3 .3 .3" 
            width="256" height="256"/>  
	
        <material name='field' texture="texplane" texrepeat="1 1" texuniform="true"/>
        <material name='geom' rgba="0.8 0.6 .4 1"/>
	</asset>

    <worldbody> 

        <light directional="false" cutoff="65" exponent="10" diffuse=".7 .7 .7" pos="0.4 -0.2 3.5" dir="-0.4 0.2 -1.5" specular=".3 .3 .3"/>

		<geom type="hfield" pos="0 0 -1" axisangle="1 0 0 0" hfield="fld" material="field" rgba="1 1 1 1"/>	

		<geom type="plane" pos="0 0 -1.5" size="8 8 1" rgba=".8 .1 .1 1" condim="3"/>	

      	<geom type="plane" pos="-8 0 0" zaxis="1 0 0" size="1.5 8 1" rgba=".8 .1 .1 1"/> 
      	<geom type="plane" pos="8 0 0" zaxis="-1 0 0" size="1.5 8 1" rgba=".8 .1 .1 1"/> 
      	<geom type="plane" pos="0 -8 0" zaxis="0 1 0" size="8 1.5 1" rgba=".8 .1 .1 1"/> 
      	<geom type="plane" pos="0 8 0" zaxis="0 -1 0" size="8 1.5 1" rgba=".8 .1 .1 1"/> 

        <body name='torso' pos='0 0 2'>

            <freejoint name="root"/>
            <geom name='torso1' type='capsule' fromto='0 -.07 0 0 .07 0'  size='0.07'/>
            <geom name='head' type='sphere' pos='0 0 .19' size='.09'/>
            <geom name='uwaist' type='capsule' fromto='-.01 -.06 -.12 -.01 .06 -.12' size='0.06'/>
            <body name='lwaist' pos='-.01 0 -0.260' quat='1.000 0 -0.002 0' >
                <geom name='lwaist' type='capsule' fromto='0 -.06 0 0 .06 0'  size='0.06' />
                <joint name='abdomen_z' type='hinge' pos='0 0 0.065' axis='0 0 1' range='-45 45' damping='5' stiffness='20' armature='0.02' />
                <joint name='abdomen_y' type='hinge' pos='0 0 0.065' axis='0 1 0' range='-75 30' damping='5' stiffness='10' armature='0.02' />
                <body name='pelvis' pos='0 0 -0.165' quat='1.000 0 -0.002 0' >
                    <joint name='abdomen_x' type='hinge' pos='0 0 0.1' axis='1 0 0' range='-35 35' damping='5' stiffness='10' armature='0.02' />
                    <geom name='butt' type='capsule' fromto='-.02 -.07 0 -.02 .07 0'  size='0.09' />
                    <body name='right_thigh' pos='0 -0.1 -0.04' >
                        <joint name='right_hip_x' type='hinge' pos='0 0 0' axis='1 0 0' range='-25 5'   damping='5' stiffness='10' armature='0.01' />
                        <joint name='right_hip_z' type='hinge' pos='0 0 0' axis='0 0 1' range='-60 35'  damping='5' stiffness='10' armature='0.01' />
                        <joint name='right_hip_y' type='hinge' pos='0 0 0' axis='0 1 0' range='-120 20' damping='5' stiffness='20' armature='0.01' />
                        <geom name='right_thigh1' type='capsule' fromto='0 0 0 0 0.01 -.34'  size='0.06' />
                        <body name='right_shin' pos='0 0.01 -0.403' >
                            <joint name='right_knee' type='hinge' pos='0 0 .02' axis='0 -1 0' range='-160 -2' stiffness='1' armature='0.0060' />
                            <geom name='right_shin1' type='capsule' fromto='0 0 0 0 0 -.3'   size='0.049' />
                            <body name='right_foot' pos='0 0 -.39' >
                                <joint name='right_ankle_y' type='hinge' pos='0 0 0.08' axis='0 1 0'   range='-50 50' stiffness='4' armature='0.0008' />
                                <joint name='right_ankle_x' type='hinge' pos='0 0 0.04' axis='1 0 0.5' range='-50 50' stiffness='1'  armature='0.0006' />
                                <geom name='right_foot_cap1' type='capsule' fromto='-.07 -0.02 0 0.14 -0.04 0'  size='0.027' />
                                <geom name='right_foot_cap2' type='capsule' fromto='-.07 0 0 0.14  0.02 0'  size='0.027' />
                            </body>
                        </body>
                    </body>
                    <body name='left_thigh' pos='0 0.1 -0.04' >
                        <joint name='left_hip_x' type='hinge' pos='0 0 0' axis='-1 0 0' range='-25 5'  damping='5' stiffness='10' armature='0.01' />
                        <joint name='left_hip_z' type='hinge' pos='0 0 0' axis='0 0 -1' range='-60 35' damping='5' stiffness='10' armature='0.01' />
                        <joint name='left_hip_y' type='hinge' pos='0 0 0' axis='0 1 0' range='-120 20' damping='5' stiffness='20' armature='0.01' />
                        <geom name='left_thigh1' type='capsule' fromto='0 0 0 0 -0.01 -.34'  size='0.06' />
                        <body name='left_shin' pos='0 -0.01 -0.403' >
                            <joint name='left_knee' type='hinge' pos='0 0 .02' axis='0 -1 0' range='-160 -2' stiffness='1' armature='0.0060' />
                            <geom name='left_shin1' type='capsule' fromto='0 0 0 0 0 -.3'   size='0.049' />
                            <body name='left_foot' pos='0 0 -.39' >
                                <joint name='left_ankle_y' type='hinge' pos='0 0 0.08' axis='0 1 0'   range='-50 50'  stiffness='4' armature='0.0008' />
                                <joint name='left_ankle_x' type='hinge' pos='0 0 0.04' axis='1 0 0.5' range='-50 50'  stiffness='1'  armature='0.0006' />
                                <geom name='left_foot_cap1' type='capsule' fromto='-.07 0.02 0 0.14 0.04 0'  size='0.027' />
                                <geom name='left_foot_cap2' type='capsule' fromto='-.07 0 0 0.14  -0.02 0'  size='0.027' />
                            </body>
                        </body>
                    </body>
                </body>
            </body>
            <body name='right_upper_arm' pos='0 -0.17 0.06' >
                <joint name='right_shoulder1' type='hinge' pos='0 0 0' axis='2 1 1'  range='-85 60' stiffness='1' armature='0.0068' />
                <joint name='right_shoulder2' type='hinge' pos='0 0 0' axis='0 -1 1' range='-85 60' stiffness='1'  armature='0.0051' />
                <geom name='right_uarm1' type='capsule' fromto='0 0 0 .16 -.16 -.16'  size='0.04 0.16' />
                <body name='right_lower_arm' pos='.18 -.18 -.18' >
                    <joint name='right_elbow' type='hinge' pos='0 0 0' axis='0 -1 1' range='-90 50'  stiffness='0' armature='0.0028' />
                    <geom name='right_larm' type='capsule' fromto='0.01 0.01 0.01 .17 .17 .17'  size='0.031' />
                    <geom name='right_hand' type='sphere' pos='.18 .18 .18'  size='0.04'/>
                </body>
            </body>
            <body name='left_upper_arm' pos='0 0.17 0.06' >
                <joint name='left_shoulder1' type='hinge' pos='0 0 0' axis='2 -1 1' range='-60 85' stiffness='1' armature='0.0068' />
                <joint name='left_shoulder2' type='hinge' pos='0 0 0' axis='0 1 1' range='-60 85'  stiffness='1' armature='0.0051' />
                <geom name='left_uarm1' type='capsule' fromto='0 0 0 .16 .16 -.16'  size='0.04 0.16' />
                <body name='left_lower_arm' pos='.18 .18 -.18' >
                    <joint name='left_elbow' type='hinge' pos='0 0 0' axis='0 -1 -1' range='-90 50' stiffness='0' armature='0.0028' />
                    <geom name='left_larm' type='capsule' fromto='0.01 -0.01 0.01 .17 -.17 .17'  size='0.031' />
                    <geom name='left_hand' type='sphere' pos='.18 -.18 .18'  size='0.04'/>
                </body>
            </body>
        </body>	
	</worldbody>
	
</mujoco>
